Workbook
Name A: #REF!
Name B: #REF!
Name d: #REF!
Name e: #REF!
Name f: #REF!
Name g: #REF!
Name h: #REF!
Name IQRThomsonEstM343: #REF!
Name IQRThomsonEstM344: #REF!
Name IQRThomsonEstM345: #REF!
Name IQRThomsonEstM346: #REF!
Name IQRThomsonEstM347: #REF!
Name IQRThomsonEstM348: #REF!
Name IQRThomsonEstM351: #REF!
Name IQRThomsonEstM352: #REF!
Name IQRThomsonEstM365: #REF!
Name IQRThomsonEstM366: #REF!
Name IQRThomsonEstM373: #REF!
Name IQRThomsonEstM374: #REF!
Name IQRThomsonEstM375: #REF!
Name IQRThomsonEstM376: #REF!
Name IQRThomsonEstM377: #REF!
Name IQRThomsonEstM378: #REF!
Name IQRThomsonEstM387: #REF!
Name IQRThomsonEstM388: #REF!
Name IQRThomsonEstM395: #REF!
Name IQRThomsonEstM396: #REF!
Name IQRThomsonEstM419: #REF!
Name IQRThomsonEstM420: #REF!

Sheet Instructions
A7: Building your Plan
B8: Performance Tab: | D8: A summary of the Bottoms Up Model vs your actual results on revenue and Leading Indicators of Unit Economics.
B10: Model Assumptions Tab: | D10: Fill in the BLUE numbers in the Model Assumptions column. These will populate in the monthly assumptions columns.
D11: We recommend you start with your current results to get a baseline model.
B13: GTM Bottoms Up Model: | D13: Add your headcount including ramp for your AEs and SDRs
D14: Everything else will populate based on your inputs from the Model Assumptions tab.
B15: LIR: | D15: A worksheet to track your Leading Indicator of Retention.
A18: Definitions | C18: You can change these to whatever language you use internally.
B19: TOFU | C19: Top of funnel leads
B20: Contacts | C20: A Contact in an accounts prospected for outbound
B21: MQL | C21: Marketing Qualified Lead for inbound leads
B22: SQL | C22: Sales Qualified lead - qualified opportunities you add to your pipeline
B23: ACV | C23: Average 1 year contract value

Sheet Performance Plan vs. Actual
A1: 2024 Plan
A2: Fill in the cells in yellow | O2: 2025
B3: 45658 | C3: =EDATE(B3,1) -> 45689 | D3: =EDATE(C3,1) -> 45717 | E3: =EDATE(D3,1) -> 45748 | F3: =EDATE(E3,1) -> 45778 | G3: =EDATE(F3,1) -> 45809 | H3: =EDATE(G3,1) -> 45839 | I3: =EDATE(H3,1) -> 45870 | J3: =EDATE(I3,1) -> 45901 | ... M3: =EDATE(L3,1) -> 45992 | O3: Q1 | P3: Q2 | Q3: Q3 | R3: Q4 | S3: TOTAL
A4: Revenue
A5: Starting ARR | B5: 0 | C5: =B10 -> 63000 | D5: =C10 -> 124740 | E5: =D10 -> 185245.2 | F5: =E10 -> 274540.3 | G5: =F10 -> 362049.49 | H5: =G10 -> 447808.5 | I5: =H10 -> 571227.33 | J5: =I10 -> 725927.78 | ... M5: =L10 -> 1321793.1
A6: New | B6: ='GTM Bottoms up Model'!B30 -> 60000 | C6: ='GTM Bottoms up Model'!C30 -> 60000 | D6: ='GTM Bottoms up Model'!D30 -> 60000 | E6: ='GTM Bottoms up Model'!E30 -> 90000 | F6: ='GTM Bottoms up Model'!F30 -> 90000 | G6: ='GTM Bottoms up Model'!G30 -> 90000 | H6: ='GTM Bottoms up Model'!H30 -> 129375 | I6: ='GTM Bottoms up Model'!I30 -> 163125 | ... M6: ='GTM Bottoms up Model'!M30 -> 241875 | O6: =SUM(B6:D6) -> 180000 | P6: =SUM(E6:G6) -> 270000 | Q6: =SUM(H6:J6) -> 472500 | R6: =SUM(K6:M6) -> 703125 | S6: =SUM(O6:R6) -> 1625625
A7: Expansion | B7: ='GTM Bottoms up Model'!B32 -> 6000 | C7: ='GTM Bottoms up Model'!C32 -> 6000 | D7: ='GTM Bottoms up Model'!D32 -> 6000 | E7: ='GTM Bottoms up Model'!E32 -> 6000 | F7: ='GTM Bottoms up Model'!F32 -> 6000 | G7: ='GTM Bottoms up Model'!G32 -> 6000 | H7: ='GTM Bottoms up Model'!H32 -> 6000 | I7: ='GTM Bottoms up Model'!I32 -> 6000 | ... M7: ='GTM Bottoms up Model'!M32 -> 6000 | O7: =SUM(B7:D7) -> 18000 | P7: =SUM(E7:G7) -> 18000 | Q7: =SUM(H7:J7) -> 18000 | R7: =SUM(K7:M7) -> 18000 | S7: =SUM(O7:R7) -> 72000
A8: Contraction | B8: -3000 | C8: -3000 | D8: -3000 | E8: -3000 | F8: -3000 | G8: -3000 | H8: -3000 | I8: -3000 | J8: -3000 | K8: -3000 | L8: -3000 | M8: -3000
A9: Churn | B9: =-SUM(B5*0.02) -> 0 | C9: =-SUM(C5*0.02) -> -1260 | D9: =-SUM(D5*0.02) -> -2494.8 | E9: =-SUM(E5*0.02) -> -3704.904 | F9: =-SUM(F5*0.02) -> -5490.8059 | G9: =-SUM(G5*0.02) -> -7240.9898 | H9: =-SUM(H5*0.02) -> -8956.17 | I9: =-SUM(I5*0.02) -> -11424.547 | ... M9: =-SUM(M5*0.02) -> -26435.862
A10: Total | B10: =SUM(B5:B9) -> 63000 | C10: =SUM(C5:C9) -> 124740 | D10: =SUM(D5:D9) -> 185245.2 | E10: =SUM(E5:E9) -> 274540.3 | F10: =SUM(F5:F9) -> 362049.49 | G10: =SUM(G5:G9) -> 447808.5 | H10: =SUM(H5:H9) -> 571227.33 | I10: =SUM(I5:I9) -> 725927.78 | ... M10: =SUM(M5:M9) -> 1540232.3 | O10: =SUM(B10:D10) -> 372985.2 | P10: =SUM(E10:G10) -> 1084398.3 | Q10: =SUM(H10:J10) -> 2191564.3 | R10: =SUM(K10:M10) -> 3960921.4 | S10: =SUM(O10:R10) -> 7609869.3
A11: New Customers | B11: ='GTM Bottoms up Model'!B29 -> 4 | C11: ='GTM Bottoms up Model'!C29 -> 4 | D11: ='GTM Bottoms up Model'!D29 -> 4 | E11: ='GTM Bottoms up Model'!E29 -> 4 | F11: ='GTM Bottoms up Model'!F29 -> 4 | G11: ='GTM Bottoms up Model'!G29 -> 4 | H11: ='GTM Bottoms up Model'!H29 -> 5.75 | I11: ='GTM Bottoms up Model'!I29 -> 7.25 | ... M11: ='GTM Bottoms up Model'!M29 -> 10.75 | O11: =SUM(B11:D11) -> 12 | P11: =SUM(E11:G11) -> 12 | Q11: =SUM(H11:J11) -> 21 | R11: =SUM(K11:M11) -> 31.25 | S11: =SUM(O11:R11) -> 76.25
A12: CaC payback (months) | B12: ='GTM Bottoms up Model'!B123 -> 9.570412 | C12: ='GTM Bottoms up Model'!C123 -> 9.570412 | D12: ='GTM Bottoms up Model'!D123 -> 9.570412 | E12: ='GTM Bottoms up Model'!E123 -> 10.746325 | F12: ='GTM Bottoms up Model'!F123 -> 10.746325 | G12: ='GTM Bottoms up Model'!G123 -> 12.048408 | H12: ='GTM Bottoms up Model'!H123 -> 10.412228 | I12: ='GTM Bottoms up Model'!I123 -> 8.3491384 | ... M12: ='GTM Bottoms up Model'!M123 -> 7.7372237 | O12: =AVERAGE(B12:D12) -> 9.570412 | P12: =AVERAGE(E12:G12) -> 11.180353 | Q12: =AVERAGE(H12:J12) -> 9.2346031 | R12: =AVERAGE(K12:M12) -> 7.6224901
A13: S/M expense as a % of Revenue | B13: ='GTM Bottoms up Model'!B124 -> 0.63802747 | C13: ='GTM Bottoms up Model'!C124 -> 0.63802747 | D13: ='GTM Bottoms up Model'!D124 -> 0.63802747 | E13: ='GTM Bottoms up Model'!E124 -> 0.71642166 | F13: ='GTM Bottoms up Model'!F124 -> 0.71642166 | G13: ='GTM Bottoms up Model'!G124 -> 0.80322722 | H13: ='GTM Bottoms up Model'!H124 -> 0.69414852 | I13: ='GTM Bottoms up Model'!I124 -> 0.55660923 | ... M13: ='GTM Bottoms up Model'!M124 -> 0.51581491 | O13: =AVERAGE(B13:D13) -> 0.63802747 | P13: =AVERAGE(E13:G13) -> 0.74535685 | Q13: =AVERAGE(H13:J13) -> 0.6156402 | R13: =AVERAGE(K13:M13) -> 0.50816601
A15: Demand Gen - SQLs by Channel
A16: Outbound | B16: ='GTM Bottoms up Model'!B45 -> 2.2503516 | C16: ='GTM Bottoms up Model'!C45 -> 2.2503516 | D16: ='GTM Bottoms up Model'!D45 -> 2.2503516 | E16: ='GTM Bottoms up Model'!E45 -> 2.2503516 | F16: ='GTM Bottoms up Model'!F45 -> 2.2503516 | G16: ='GTM Bottoms up Model'!G45 -> 2.2503516 | H16: ='GTM Bottoms up Model'!H45 -> 3.2348805 | I16: ='GTM Bottoms up Model'!I45 -> 4.0787623 | ... M16: ='GTM Bottoms up Model'!M45 -> 6.04782 | O16: =SUM(B16:D16) -> 6.7510549 | P16: =SUM(E16:G16) -> 6.7510549 | Q16: =SUM(H16:J16) -> 11.814346 | R16: =SUM(K16:M16) -> 17.580872 | S16: =SUM(O16:R16) -> 42.897328
A17: Inbound | B17: ='GTM Bottoms up Model'!B59 -> 9.0014065 | C17: ='GTM Bottoms up Model'!C59 -> 9.0014065 | D17: ='GTM Bottoms up Model'!D59 -> 9.0014065 | E17: ='GTM Bottoms up Model'!E59 -> 9.0014065 | F17: ='GTM Bottoms up Model'!F59 -> 9.0014065 | G17: ='GTM Bottoms up Model'!G59 -> 9.0014065 | H17: ='GTM Bottoms up Model'!H59 -> 12.939522 | I17: ='GTM Bottoms up Model'!I59 -> 16.315049 | ... M17: ='GTM Bottoms up Model'!M59 -> 24.19128 | O17: =SUM(B17:D17) -> 27.004219 | P17: =SUM(E17:G17) -> 27.004219 | Q17: =SUM(H17:J17) -> 47.257384 | R17: =SUM(K17:M17) -> 70.323488 | S17: =SUM(O17:R17) -> 171.58931
A18: Partner | B18: ='GTM Bottoms up Model'!B70 -> 0 | C18: ='GTM Bottoms up Model'!C70 -> 0 | D18: ='GTM Bottoms up Model'!D70 -> 0 | E18: ='GTM Bottoms up Model'!E70 -> 0 | F18: ='GTM Bottoms up Model'!F70 -> 0 | G18: ='GTM Bottoms up Model'!G70 -> 0 | H18: ='GTM Bottoms up Model'!H70 -> 0 | I18: ='GTM Bottoms up Model'!I70 -> 0 | ... M18: ='GTM Bottoms up Model'!M70 -> 0 | O18: =SUM(B18:D18) -> 0 | P18: =SUM(E18:G18) -> 0 | Q18: =SUM(H18:J18) -> 0 | R18: =SUM(K18:M18) -> 0 | S18: =SUM(O18:R18) -> 0
A19: Total | B19: =SUM(B16:B18) -> 11.251758 | C19: =SUM(C16:C18) -> 11.251758 | D19: =SUM(D16:D18) -> 11.251758 | E19: =SUM(E16:E18) -> 11.251758 | F19: =SUM(F16:F18) -> 11.251758 | G19: =SUM(G16:G18) -> 11.251758 | H19: =SUM(H16:H18) -> 16.174402 | I19: =SUM(I16:I18) -> 20.393812 | ... M19: =SUM(M16:M18) -> 30.2391 | O19: =SUM(B19:D19) -> 33.755274 | P19: =SUM(E19:G19) -> 33.755274 | Q19: =SUM(H19:J19) -> 59.07173 | R19: =SUM(K19:M19) -> 87.90436 | S19: =SUM(O19:R19) -> 214.48664
A21: Leading Indicators of Unit Economics
A22: SQLs per Rep | B22: ='GTM Bottoms up Model'!B126 -> 5.625879 | C22: ='GTM Bottoms up Model'!C126 -> 5.625879 | D22: ='GTM Bottoms up Model'!D126 -> 5.625879 | E22: ='GTM Bottoms up Model'!E126 -> 5.625879 | F22: ='GTM Bottoms up Model'!F126 -> 5.625879 | G22: ='GTM Bottoms up Model'!G126 -> 5.625879 | H22: ='GTM Bottoms up Model'!H126 -> 5.3914674 | I22: ='GTM Bottoms up Model'!I126 -> 6.7979372 | ... M22: ='GTM Bottoms up Model'!M126 -> 6.04782 | O22: =AVERAGE(B22:D22) -> 5.625879 | P22: =AVERAGE(E22:G22) -> 5.625879 | Q22: =AVERAGE(H22:J22) -> 5.9384279 | R22: =AVERAGE(K22:M22) -> 6.3173933 | S22: =AVERAGE(O22:R22) -> 5.8768948
A23: Deals per Rep | B23: ='GTM Bottoms up Model'!B127 -> 2 | C23: ='GTM Bottoms up Model'!C127 -> 2 | D23: ='GTM Bottoms up Model'!D127 -> 2 | E23: ='GTM Bottoms up Model'!E127 -> 2 | F23: ='GTM Bottoms up Model'!F127 -> 2 | G23: ='GTM Bottoms up Model'!G127 -> 2 | H23: ='GTM Bottoms up Model'!H127 -> 2.5 | I23: ='GTM Bottoms up Model'!I127 -> 2.5 | ... M23: ='GTM Bottoms up Model'!M127 -> 2.5 | O23: =AVERAGE(B23:D23) -> 2 | P23: =AVERAGE(E23:G23) -> 2 | Q23: =AVERAGE(H23:J23) -> 2.5 | R23: =AVERAGE(K23:M23) -> 2.5 | S23: =AVERAGE(O23:R23) -> 2.25
A24: ACV | B24: ='GTM Bottoms up Model'!B128 -> 15000 | C24: ='GTM Bottoms up Model'!C128 -> 15000 | D24: ='GTM Bottoms up Model'!D128 -> 15000 | E24: ='GTM Bottoms up Model'!E128 -> 22500 | F24: ='GTM Bottoms up Model'!F128 -> 22500 | G24: ='GTM Bottoms up Model'!G128 -> 22500 | H24: ='GTM Bottoms up Model'!H128 -> 22500 | I24: ='GTM Bottoms up Model'!I128 -> 22500 | ... M24: ='GTM Bottoms up Model'!M128 -> 22500 | O24: =AVERAGE(B24:D24) -> 15000 | P24: =AVERAGE(E24:G24) -> 22500 | Q24: =AVERAGE(H24:J24) -> 22500 | R24: =AVERAGE(K24:M24) -> 22500 | S24: =AVERAGE(O24:R24) -> 20625
A25: CAC per Customer | B25: ='GTM Bottoms up Model'!B130 -> 10527.453 | C25: ='GTM Bottoms up Model'!C130 -> 10527.453 | D25: ='GTM Bottoms up Model'!D130 -> 10527.453 | E25: ='GTM Bottoms up Model'!E130 -> 17194.12 | F25: ='GTM Bottoms up Model'!F130 -> 17194.12 | G25: ='GTM Bottoms up Model'!G130 -> 19277.453 | H25: ='GTM Bottoms up Model'!H130 -> 16342.671 | I25: ='GTM Bottoms up Model'!I130 -> 12984.35 | ... M25: ='GTM Bottoms up Model'!M130 -> 11893.732 | O25: =AVERAGE(B25:D25) -> 10527.453 | P25: =AVERAGE(E25:G25) -> 17888.564 | Q25: =AVERAGE(H25:J25) -> 14395.936 | R25: =AVERAGE(K25:M25) -> 11726.767 | S25: =AVERAGE(O25:R25) -> 13634.68
A27: Headcount
A28: AE | B28: =ROUNDUP('GTM Bottoms up Model'!B19,0) -> 2 | C28: =ROUNDUP('GTM Bottoms up Model'!C19,0) -> 2 | D28: =ROUNDUP('GTM Bottoms up Model'!D19,0) -> 2 | E28: 1 | F28: =ROUNDUP('GTM Bottoms up Model'!F19,0) -> 2 | G28: =ROUNDUP('GTM Bottoms up Model'!G19,0) -> 2 | H28: =ROUNDUP('GTM Bottoms up Model'!H19,0) -> 3 | I28: =ROUNDUP('GTM Bottoms up Model'!I19,0) -> 3 | J28: =ROUNDUP('GTM Bottoms up Model'!J19,0) -> 4 | K28: =ROUNDUP('GTM Bottoms up Model'!K19,0) -> 4 | L28: =ROUNDUP('GTM Bottoms up Model'!L19,0) -> 5 | M28: =ROUNDUP('GTM Bottoms up Model'!M19,0) -> 5 | O28: =D28 -> 2 | P28: =G28 -> 2 | Q28: =J28 -> 4 | R28: =M28 -> 5 | S28: =R28 -> 5
A29: CS | B29: =ROUNDUP('GTM Bottoms up Model'!B20,0) -> 1 | C29: =ROUNDUP('GTM Bottoms up Model'!C20,0) -> 1 | D29: =ROUNDUP('GTM Bottoms up Model'!D20,0) -> 1 | E29: =ROUNDUP('GTM Bottoms up Model'!E20,0) -> 1 | F29: =ROUNDUP('GTM Bottoms up Model'!F20,0) -> 1 | G29: =ROUNDUP('GTM Bottoms up Model'!G20,0) -> 1 | H29: =ROUNDUP('GTM Bottoms up Model'!H20,0) -> 1 | I29: =ROUNDUP('GTM Bottoms up Model'!I20,0) -> 1 | ... M29: =ROUNDUP('GTM Bottoms up Model'!M20,0) -> 1 | O29: =D29 -> 1 | P29: =G29 -> 1 | Q29: =J29 -> 1 | R29: =M29 -> 1 | S29: =R29 -> 1
A30: SDR | B30: =ROUNDUP('GTM Bottoms up Model'!B21,0) -> 1 | C30: =ROUNDUP('GTM Bottoms up Model'!C21,0) -> 1 | D30: =ROUNDUP('GTM Bottoms up Model'!D21,0) -> 1 | E30: =ROUNDUP('GTM Bottoms up Model'!E21,0) -> 1 | F30: =ROUNDUP('GTM Bottoms up Model'!F21,0) -> 1 | G30: =ROUNDUP('GTM Bottoms up Model'!G21,0) -> 2 | H30: =ROUNDUP('GTM Bottoms up Model'!H21,0) -> 2 | I30: =ROUNDUP('GTM Bottoms up Model'!I21,0) -> 2 | ... M30: =ROUNDUP('GTM Bottoms up Model'!M21,0) -> 2 | O30: =D30 -> 1 | P30: =G30 -> 2 | Q30: =J30 -> 2 | R30: =M30 -> 2 | S30: =R30 -> 2
A31: Total | B31: =SUM(B28:B30) -> 4 | C31: =SUM(C28:C30) -> 4 | D31: =SUM(D28:D30) -> 4 | E31: =SUM(E28:E30) -> 3 | F31: =SUM(F28:F30) -> 4 | G31: =SUM(G28:G30) -> 5 | H31: =SUM(H28:H30) -> 6 | I31: =SUM(I28:I30) -> 6 | ... M31: =SUM(M28:M30) -> 8 | O31: =D31 -> 4 | P31: =G31 -> 5 | Q31: =J31 -> 7 | R31: =M31 -> 8 | S31: =R31 -> 8
A33: Cash
A34: Beginning Balance
A35: Change in Cash
A36: Ending Balance
A37: Runway | B37: =IFERROR((B36/B35)*12,"NA") -> NA | C37: =IFERROR((C36/C35)*12,"NA") -> NA | D37: =IFERROR((D36/D35)*12,"NA") -> NA | E37: =IFERROR((E36/E35)*12,"NA") -> NA | F37: =IFERROR((F36/F35)*12,"NA") -> NA | G37: =IFERROR((G36/G35)*12,"NA") -> NA | H37: =IFERROR((H36/H35)*12,"NA") -> NA | I37: =IFERROR((I36/I35)*12,"NA") -> NA | ... M37: =IFERROR((M36/M35)*12,"NA") -> NA
A39: ACTUAL
A40: Fill in the cells in yellow
A42: Revenue
A43: Starting ARR | C43: =B48 -> 0 | D43: =C48 -> 0 | E43: =D48 -> 0 | F43: =E48 -> 0 | G43: =F48 -> 0 | H43: =G48 -> 0 | I43: =H48 -> 0 | J43: =I48 -> 0 | ... M43: =L48 -> 0
A44: New
A45: Expansion
A46: Contraction
...

Sheet Model Assumptions
A1: Exchange | B1: 1.4
B2: Model Assumptions: Fill in the BLUE numbers in the assumptions column. You can override the autopopulation if you want to adjust by month.
B3: GTM Bottoms Up Model: Fill in the hiring plan in blue.
E5: Model Assumptions | G5: 45658 | H5: =EDATE(G5,1) -> 45689 | I5: =EDATE(H5,1) -> 45717 | J5: =EDATE(I5,1) -> 45748 | K5: =EDATE(J5,1) -> 45778 | L5: =EDATE(K5,1) -> 45809 | M5: =EDATE(L5,1) -> 45839 | N5: =EDATE(M5,1) -> 45870 | O5: =EDATE(N5,1) -> 45901 | ... R5: =EDATE(Q5,1) -> 45992
B6: Productivity
B7: AE
B8: Aggregate Average ACV | E8: 15000 | G8: =$E$8 -> 15000 | H8: =$E$8 -> 15000 | I8: =$E$8 -> 15000 | J8: 22500 | K8: 22500 | L8: 22500 | M8: 22500 | N8: 22500 | O8: 22500 | P8: 22500 | Q8: 22500 | R8: 22500
B9: New Customers Signed per Rep | E9: 2 | G9: =$E$9 -> 2 | H9: =$E$9 -> 2 | I9: =$E$9 -> 2 | J9: =$E$9 -> 2 | K9: =$E$9 -> 2 | L9: =$E$9 -> 2 | M9: 2.5 | N9: 2.5 | O9: 2.5 | P9: 2.5 | Q9: 2.5 | R9: 2.5
B10: CS
B11: Average Expansion ACV | E11: 3000 | G11: =$E$11 -> 3000 | H11: =$E$11 -> 3000 | I11: =$E$11 -> 3000 | J11: =$E$11 -> 3000 | K11: =$E$11 -> 3000 | L11: =$E$11 -> 3000 | M11: =$E$11 -> 3000 | N11: =$E$11 -> 3000 | ... R11: =$E$11 -> 3000
B12: Expansions per rep | E12: 2 | G12: =$E$12 -> 2 | H12: =$E$12 -> 2 | I12: =$E$12 -> 2 | J12: =$E$12 -> 2 | K12: =$E$12 -> 2 | L12: =$E$12 -> 2 | M12: =$E$12 -> 2 | N12: =$E$12 -> 2 | ... R12: =$E$12 -> 2
B14: Gross Margin | E14: 0.8 | G14: =$E$14 -> 0.8 | H14: =$E$14 -> 0.8 | I14: =$E$14 -> 0.8 | J14: =$E$14 -> 0.8 | K14: =$E$14 -> 0.8 | L14: =$E$14 -> 0.8 | M14: =$E$14 -> 0.8 | N14: =$E$14 -> 0.8 | ... R14: =$E$14 -> 0.8
B16: Demand Gen Channels - Deals Closed by channel
B17: Inbound | E17: 0.8 | G17: =$E$17 -> 0.8 | H17: =$E$17 -> 0.8 | I17: =$E$17 -> 0.8 | J17: =$E$17 -> 0.8 | K17: =$E$17 -> 0.8 | L17: =$E$17 -> 0.8 | M17: =$E$17 -> 0.8 | N17: =$E$17 -> 0.8 | ... R17: =$E$17 -> 0.8
B18: Outbound | E18: 0.2 | G18: =$E$18 -> 0.2 | H18: =$E$18 -> 0.2 | I18: =$E$18 -> 0.2 | J18: =$E$18 -> 0.2 | K18: =$E$18 -> 0.2 | L18: =$E$18 -> 0.2 | M18: =$E$18 -> 0.2 | N18: =$E$18 -> 0.2 | ... R18: =$E$18 -> 0.2
B19: Partners | E19: 0 | G19: =$E$19 -> 0 | H19: =$E$19 -> 0 | I19: =$E$19 -> 0 | J19: =$E$19 -> 0 | K19: =$E$19 -> 0 | L19: =$E$19 -> 0 | M19: =$E$19 -> 0 | N19: =$E$19 -> 0 | ... R19: =$E$19 -> 0
B21: Demand Generation Performance
B22: Channel 1: Inbound
B23: Marketing Spend per Month per Rep | E23: =E26*E30 -> 49.853944 | G23: =$E$23 -> 49.853944 | H23: =$E$23 -> 49.853944 | I23: =$E$23 -> 49.853944 | J23: =$E$23 -> 49.853944 | K23: =$E$23 -> 49.853944 | L23: =$E$23 -> 49.853944 | M23: =$E$23 -> 49.853944 | N23: =$E$23 -> 49.853944 | ... R23: =$E$23 -> 49.853944
B24: Deals per Rep | E24: =AVERAGE(E9)*E17 -> 1.6 | G24: =$E$24 -> 1.6 | H24: =$E$24 -> 1.6 | I24: =$E$24 -> 1.6 | J24: =$E$24 -> 1.6 | K24: =$E$24 -> 1.6 | L24: =$E$24 -> 1.6 | M24: =$E$24 -> 1.6 | N24: =$E$24 -> 1.6 | ... R24: =$E$24 -> 1.6
B25: SQLs per Rep | E25: =E24/E29 -> 2.0253165 | G25: =$E$25 -> 2.0253165 | H25: =$E$25 -> 2.0253165 | I25: =$E$25 -> 2.0253165 | J25: =$E$25 -> 2.0253165 | K25: =$E$25 -> 2.0253165 | L25: =$E$25 -> 2.0253165 | M25: =$E$25 -> 2.0253165 | N25: =$E$25 -> 2.0253165 | ... R25: =$E$25 -> 2.0253165
B26: TOFU Leads per Rep | E26: =E25/E27 -> 3.1158715 | G26: =$E$26 -> 3.1158715 | H26: =$E$26 -> 3.1158715 | I26: =$E$26 -> 3.1158715 | J26: =$E$26 -> 3.1158715 | K26: =$E$26 -> 3.1158715 | L26: =$E$26 -> 3.1158715 | M26: =$E$26 -> 3.1158715 | N26: =$E$26 -> 3.1158715 | ... R26: =$E$26 -> 3.1158715
B27: Lead to SQL Conversion (demo) | E27: 0.65 | G27: =$E$27 -> 0.65 | H27: =$E$27 -> 0.65 | I27: =$E$27 -> 0.65 | J27: =$E$27 -> 0.65 | K27: =$E$27 -> 0.65 | L27: =$E$27 -> 0.65 | M27: =$E$27 -> 0.65 | N27: =$E$27 -> 0.65 | ... R27: =$E$27 -> 0.65
B28: Demo to Eval | E28: 0.45 | G28: =$E$28 -> 0.45 | H28: =$E$28 -> 0.45 | I28: =$E$28 -> 0.45 | J28: =$E$28 -> 0.45 | K28: =$E$28 -> 0.45 | L28: =$E$28 -> 0.45 | M28: =$E$28 -> 0.45 | N28: =$E$28 -> 0.45 | ... R28: =$E$28 -> 0.45
B29: Eval to Contracting | E29: 0.79 | G29: =$E$29 -> 0.79 | H29: =$E$29 -> 0.79 | I29: =$E$29 -> 0.79 | J29: =$E$29 -> 0.79 | K29: =$E$29 -> 0.79 | L29: =$E$29 -> 0.79 | M29: =$E$29 -> 0.79 | N29: =$E$29 -> 0.79 | ... R29: =$E$29 -> 0.79
B30: Cost per TOFU Lead | E30: 16 | G30: =$E$30 -> 16 | H30: =$E$30 -> 16 | I30: =$E$30 -> 16 | J30: =$E$30 -> 16 | K30: =$E$30 -> 16 | L30: =$E$30 -> 16 | M30: =$E$30 -> 16 | N30: =$E$30 -> 16 | ... R30: =$E$30 -> 16
B31: Channel 2: Outbound
B32: SDR Accounts Needed # | E32: =E34/E36*2 -> 3.9506173 | G32: =$E$32 -> 3.9506173 | H32: =$E$32 -> 3.9506173 | I32: =$E$32 -> 3.9506173 | J32: =$E$32 -> 3.9506173 | K32: =$E$32 -> 3.9506173 | L32: =$E$32 -> 3.9506173 | M32: =$E$32 -> 3.9506173 | N32: =$E$32 -> 3.9506173 | ... R32: =$E$32 -> 3.9506173
B33: Deals per Rep | E33: =AVERAGE(E9)*E18 -> 0.4 | G33: =$E$33 -> 0.4 | H33: =$E$33 -> 0.4 | I33: =$E$33 -> 0.4 | J33: =$E$33 -> 0.4 | K33: =$E$33 -> 0.4 | L33: =$E$33 -> 0.4 | M33: =$E$33 -> 0.4 | N33: =$E$33 -> 0.4 | ... R33: =$E$33 -> 0.4
B34: SQLs per Rep | E34: =E33/E36 -> 0.88888889 | G34: =$E$34 -> 0.88888889 | H34: =$E$34 -> 0.88888889 | I34: =$E$34 -> 0.88888889 | J34: =$E$34 -> 0.88888889 | K34: =$E$34 -> 0.88888889 | L34: =$E$34 -> 0.88888889 | M34: =$E$34 -> 0.88888889 | N34: =$E$34 -> 0.88888889 | ... R34: =$E$34 -> 0.88888889
B35: Contacts to SQL Conversion (demo) | E35: 0.03 | G35: =$E$35 -> 0.03 | H35: =$E$35 -> 0.03 | I35: =$E$35 -> 0.03 | J35: =$E$35 -> 0.03 | K35: =$E$35 -> 0.03 | L35: =$E$35 -> 0.03 | M35: =$E$35 -> 0.03 | N35: =$E$35 -> 0.03 | ... R35: =$E$35 -> 0.03
B36: Outbound SQL to Pilot | E36: 0.45 | G36: =$E$36 -> 0.45 | H36: =$E$36 -> 0.45 | I36: =$E$36 -> 0.45 | J36: =$E$36 -> 0.45 | K36: =$E$36 -> 0.45 | L36: =$E$36 -> 0.45 | M36: =$E$36 -> 0.45 | N36: =$E$36 -> 0.45 | ... R36: =$E$36 -> 0.45
B37: Pilot to Customer Conversion | E37: 0.79 | G37: =$E$37 -> 0.79 | H37: =$E$37 -> 0.79 | I37: =$E$37 -> 0.79 | J37: =$E$37 -> 0.79 | K37: =$E$37 -> 0.79 | L37: =$E$37 -> 0.79 | M37: =$E$37 -> 0.79 | N37: =$E$37 -> 0.79 | ... R37: =$E$37 -> 0.79
B38: SDR to AE Ratio | E38: 2 | G38: =$E$38 -> 2 | H38: =$E$38 -> 2 | I38: =$E$38 -> 2 | J38: =$E$38 -> 2 | K38: =$E$38 -> 2 | L38: =$E$38 -> 2 | M38: =$E$38 -> 2 | N38: =$E$38 -> 2 | ... R38: =$E$38 -> 2
B39: Channel 3: Partners
B40: Partner Compensation per Lead | E40: 0 | G40: =$E$40 -> 0 | H40: =$E$40 -> 0 | I40: =$E$40 -> 0 | J40: =$E$40 -> 0 | K40: =$E$40 -> 0 | L40: =$E$40 -> 0 | M40: =$E$40 -> 0 | N40: =$E$40 -> 0 | ... R40: =$E$40 -> 0
B41: Partner Deals per Rep | E41: =AVERAGE(E9)*E19 -> 0 | G41: =$E$41 -> 0 | H41: =$E$41 -> 0 | I41: =$E$41 -> 0 | J41: =$E$41 -> 0 | K41: =$E$41 -> 0 | L41: =$E$41 -> 0 | M41: =$E$41 -> 0 | N41: =$E$41 -> 0 | ... R41: =$E$41 -> 0
B42: Partner TOFU Leads to SQL Conversion | E42: 0.1 | G42: =$E$42 -> 0.1 | H42: =$E$42 -> 0.1 | I42: =$E$42 -> 0.1 | J42: =$E$42 -> 0.1 | K42: =$E$42 -> 0.1 | L42: =$E$42 -> 0.1 | M42: =$E$42 -> 0.1 | N42: =$E$42 -> 0.1 | ... R42: =$E$42 -> 0.1
B43: Partner SQL to Customer Conversion | E43: 0.2 | G43: =$E$43 -> 0.2 | H43: =$E$43 -> 0.2 | I43: =$E$43 -> 0.2 | J43: =$E$43 -> 0.2 | K43: =$E$43 -> 0.2 | L43: =$E$43 -> 0.2 | M43: =$E$43 -> 0.2 | N43: =$E$43 -> 0.2 | ... R43: =$E$43 -> 0.2
B46: Headcount Cost (Annual)
...

Sheet GTM Bottoms up Model
A2: Sales Team: Including Ramp | C2: =B2+1 -> 1 | D2: =C2+1 -> 2 | E2: =D2+1 -> 3 | F2: =E2+1 -> 4 | G2: =F2+1 -> 5 | H2: =G2+1 -> 6 | I2: =H2+1 -> 7 | J2: =I2+1 -> 8 | ... M2: =L2+1 -> 11
B3: 45658 | C3: =EDATE(B3,1) -> 45689 | D3: =EDATE(C3,1) -> 45717 | E3: =EDATE(D3,1) -> 45748 | F3: =EDATE(E3,1) -> 45778 | G3: =EDATE(F3,1) -> 45809 | H3: =EDATE(G3,1) -> 45839 | I3: =EDATE(H3,1) -> 45870 | J3: =EDATE(I3,1) -> 45901 | ... M3: =EDATE(L3,1) -> 45992
A5: Headcount
A6: AE Headcount
A7: VP Sales / Sales Leader ( ) | B7: 0 | C7: 0 | D7: 0 | E7: 1 | F7: 1 | G7: 1 | H7: 1 | I7: 1 | J7: 1 | K7: 1 | L7: 1 | M7: 1
A8: AEI Quota | B8: =SUM('Model Assumptions'!G8*'Model Assumptions'!G9) -> 30000 | C8: =SUM('Model Assumptions'!H8*'Model Assumptions'!H9) -> 30000 | D8: =SUM('Model Assumptions'!I8*'Model Assumptions'!I9) -> 30000 | E8: =SUM('Model Assumptions'!J8*'Model Assumptions'!J9) -> 45000 | F8: =SUM('Model Assumptions'!K8*'Model Assumptions'!K9) -> 45000 | G8: =SUM('Model Assumptions'!L8*'Model Assumptions'!L9) -> 45000 | H8: =SUM('Model Assumptions'!M8*'Model Assumptions'!M9) -> 56250 | I8: =SUM('Model Assumptions'!N8*'Model Assumptions'!N9) -> 56250 | ... M8: =SUM('Model Assumptions'!R8*'Model Assumptions'!R9) -> 56250
A9: AE0 | B9: 1 | C9: 1 | D9: 1 | E9: 1 | F9: 1 | G9: 1 | H9: 1 | I9: 1 | J9: 1 | K9: 1 | L9: 1 | M9: 1
A10: AE1 | B10: 1 | C10: 1 | D10: 1 | E10: 1 | F10: 1 | G10: 1 | H10: 1 | I10: 1 | J10: 1 | K10: 1 | L10: 1 | M10: 1
A11: AE2 | B11: 0 | C11: 0 | D11: 0 | E11: 0 | F11: 0 | G11: 0 | H11: 0.3 | I11: 0.6 | J11: 0.6 | K11: 1 | L11: 1 | M11: 1
A12: AE3 | B12: 0 | C12: 0 | D12: 0 | E12: 0 | F12: 0 | G12: 0 | H12: 0 | I12: 0.3 | J12: 0.6 | K12: 0.6 | L12: 1 | M12: 1
A13: AE4 | K13: 0.3 | L13: 0.3 | M13: 0.3
A14: AE5
A15: Customer Success / AM Quota
A16: CS 1 TBH | B16: 1 | C16: 1 | D16: 1 | E16: 1 | F16: 1 | G16: 1 | H16: 1 | I16: 1 | J16: 1 | K16: 1 | L16: 1 | M16: 1
A17: CS2
A18: CS3
A19: AEs | B19: =SUM(B9:B14) -> 2 | C19: =SUM(C9:C14) -> 2 | D19: =SUM(D9:D14) -> 2 | E19: =SUM(E9:E14) -> 2 | F19: =SUM(F9:F14) -> 2 | G19: =SUM(G9:G14) -> 2 | H19: =SUM(H9:H14) -> 2.3 | I19: =SUM(I9:I14) -> 2.9 | ... M19: =SUM(M9:M14) -> 4.3
A20: CS Total | B20: =SUM(B16:B18) -> 1 | C20: =SUM(C16:C18) -> 1 | D20: =SUM(D16:D18) -> 1 | E20: =SUM(E16:E18) -> 1 | F20: =SUM(F16:F18) -> 1 | G20: =SUM(G16:G18) -> 1 | H20: =SUM(H16:H18) -> 1 | I20: =SUM(I16:I18) -> 1 | ... M20: =SUM(M16:M18) -> 1
A21: SDRs Total Outbound | B21: 1 | C21: 1 | D21: 1 | E21: 1 | F21: 1 | G21: 2 | H21: 2 | I21: 2 | J21: 2 | K21: 2 | L21: 2 | M21: 2
A24: New Revenue Projections
A26: Signed Revenue
A27: Total New ARR | B27: =SUM(B32+B30) -> 66000 | C27: =SUM(C32+C30) -> 66000 | D27: =SUM(D32+D30) -> 66000 | E27: =SUM(E32+E30) -> 96000 | F27: =SUM(F32+F30) -> 96000 | G27: =SUM(G32+G30) -> 96000 | H27: =SUM(H32+H30) -> 135375 | I27: =SUM(I32+I30) -> 169125 | ... M27: =SUM(M32+M30) -> 247875
A29: New Customers | B29: =B19*'Model Assumptions'!G9 -> 4 | C29: =C19*'Model Assumptions'!H9 -> 4 | D29: =D19*'Model Assumptions'!I9 -> 4 | E29: =E19*'Model Assumptions'!J9 -> 4 | F29: =F19*'Model Assumptions'!K9 -> 4 | G29: =G19*'Model Assumptions'!L9 -> 4 | H29: =H19*'Model Assumptions'!M9 -> 5.75 | I29: =I19*'Model Assumptions'!N9 -> 7.25 | ... M29: =M19*'Model Assumptions'!R9 -> 10.75
A30: New Customer ARR | B30: =(B29*'Model Assumptions'!G8) -> 60000 | C30: =(C29*'Model Assumptions'!H8) -> 60000 | D30: =(D29*'Model Assumptions'!I8) -> 60000 | E30: =(E29*'Model Assumptions'!J8) -> 90000 | F30: =(F29*'Model Assumptions'!K8) -> 90000 | G30: =(G29*'Model Assumptions'!L8) -> 90000 | H30: =(H29*'Model Assumptions'!M8) -> 129375 | I30: =(I29*'Model Assumptions'!N8) -> 163125 | ... M30: =(M29*'Model Assumptions'!R8) -> 241875
A31: Expansion Customers | B31: =B20*'Model Assumptions'!G12 -> 2 | C31: =C20*'Model Assumptions'!H12 -> 2 | D31: =D20*'Model Assumptions'!I12 -> 2 | E31: =E20*'Model Assumptions'!J12 -> 2 | F31: =F20*'Model Assumptions'!K12 -> 2 | G31: =G20*'Model Assumptions'!L12 -> 2 | H31: =H20*'Model Assumptions'!M12 -> 2 | I31: =I20*'Model Assumptions'!N12 -> 2 | ... M31: =M20*'Model Assumptions'!R12 -> 2
A32: Expansion ARR | B32: =B31*'Model Assumptions'!G11 -> 6000 | C32: =C31*'Model Assumptions'!H11 -> 6000 | D32: =D31*'Model Assumptions'!I11 -> 6000 | E32: =E31*'Model Assumptions'!J11 -> 6000 | F32: =F31*'Model Assumptions'!K11 -> 6000 | G32: =G31*'Model Assumptions'!L11 -> 6000 | H32: =H31*'Model Assumptions'!M11 -> 6000 | I32: =I31*'Model Assumptions'!N11 -> 6000 | ... M32: =M31*'Model Assumptions'!R11 -> 6000
A34: Pipeline Needed
A35: New Customers
A36: TOFU Leads | B36: =B39/#REF! -> #REF! | C36: =C39/#REF! -> #REF! | D36: =D39/#REF! -> #REF! | E36: =E39/#REF! -> #REF! | F36: =F39/#REF! -> #REF! | G36: =G39/#REF! -> #REF! | H36: =H39/#REF! -> #REF! | I36: =I39/#REF! -> #REF! | ... M36: =M39/#REF! -> #REF!
A37: TOFU -Outbound Accounts | B37: =B44 -> 75.011721 | C37: =C44 -> 75.011721 | D37: =D44 -> 75.011721 | E37: =E44 -> 75.011721 | F37: =F44 -> 75.011721 | G37: =G44 -> 75.011721 | H37: =H44 -> 107.82935 | I37: =I44 -> 135.95874 | ... M37: =M44 -> 201.594
A38: TOFU - Inbound MQLs | B38: =B58 -> 13.848318 | C38: =C58 -> 13.848318 | D38: =D58 -> 13.848318 | E38: =E58 -> 13.848318 | F38: =F58 -> 13.848318 | G38: =G58 -> 13.848318 | H38: =H58 -> 19.906957 | I38: =I58 -> 25.100076 | ... M38: =M58 -> 37.217354
A39: Opportunities (SQLs) | B39: =SUM(B45+B59+B70) -> 11.251758 | C39: =SUM(C45+C59+C70) -> 11.251758 | D39: =SUM(D45+D59+D70) -> 11.251758 | E39: =SUM(E45+E59+E70) -> 11.251758 | F39: =SUM(F45+F59+F70) -> 11.251758 | G39: =SUM(G45+G59+G70) -> 11.251758 | H39: =SUM(H45+H59+H70) -> 16.174402 | I39: =SUM(I45+I59+I70) -> 20.393812 | ... M39: =SUM(M45+M59+M70) -> 30.2391
A40: Pilots | B40: =SUM(B46+B60) -> 5.0632911 | C40: =SUM(C46+C60) -> 5.0632911 | D40: =SUM(D46+D60) -> 5.0632911 | E40: =SUM(E46+E60) -> 5.0632911 | F40: =SUM(F46+F60) -> 5.0632911 | G40: =SUM(G46+G60) -> 5.0632911 | H40: =SUM(H46+H60) -> 7.278481 | I40: =SUM(I46+I60) -> 9.1772152 | ... M40: =SUM(M46+M60) -> 13.607595
A41: New Customers | B41: =SUM(B19*'Model Assumptions'!G9) -> 4 | C41: =SUM(C19*'Model Assumptions'!H9) -> 4 | D41: =SUM(D19*'Model Assumptions'!I9) -> 4 | E41: =SUM(E19*'Model Assumptions'!J9) -> 4 | F41: =SUM(F19*'Model Assumptions'!K9) -> 4 | G41: =SUM(G19*'Model Assumptions'!L9) -> 4 | H41: =SUM(H19*'Model Assumptions'!M9) -> 5.75 | I41: =SUM(I19*'Model Assumptions'!N9) -> 7.25 | ... M41: =SUM(M19*'Model Assumptions'!R9) -> 10.75
A42: Demand Gen Channels
A43: Channel 1: Outbound
A44: Top of Funnel Leads / Accounts Needed | B44: =B45/'Model Assumptions'!G35 -> 75.011721 | C44: =C45/'Model Assumptions'!H35 -> 75.011721 | D44: =D45/'Model Assumptions'!I35 -> 75.011721 | E44: =E45/'Model Assumptions'!J35 -> 75.011721 | F44: =F45/'Model Assumptions'!K35 -> 75.011721 | G44: =G45/'Model Assumptions'!L35 -> 75.011721 | H44: =H45/'Model Assumptions'!M35 -> 107.82935 | I44: =I45/'Model Assumptions'!N35 -> 135.95874 | ... M44: =M45/'Model Assumptions'!R35 -> 201.594
A45: SQL | B45: =B46/'Model Assumptions'!G36 -> 2.2503516 | C45: =C46/'Model Assumptions'!H36 -> 2.2503516 | D45: =D46/'Model Assumptions'!I36 -> 2.2503516 | E45: =E46/'Model Assumptions'!J36 -> 2.2503516 | F45: =F46/'Model Assumptions'!K36 -> 2.2503516 | G45: =G46/'Model Assumptions'!L36 -> 2.2503516 | H45: =H46/'Model Assumptions'!M36 -> 3.2348805 | I45: =I46/'Model Assumptions'!N36 -> 4.0787623 | ... M45: =M46/'Model Assumptions'!R36 -> 6.04782
A46: Pilot | B46: =B47/'Model Assumptions'!G37 -> 1.0126582 | C46: =C47/'Model Assumptions'!H37 -> 1.0126582 | D46: =D47/'Model Assumptions'!I37 -> 1.0126582 | E46: =E47/'Model Assumptions'!J37 -> 1.0126582 | F46: =F47/'Model Assumptions'!K37 -> 1.0126582 | G46: =G47/'Model Assumptions'!L37 -> 1.0126582 | H46: =H47/'Model Assumptions'!M37 -> 1.4556962 | I46: =I47/'Model Assumptions'!N37 -> 1.835443 | ... M46: =M47/'Model Assumptions'!R37 -> 2.721519
A47: Customers | B47: =B29*'Model Assumptions'!G18 -> 0.8 | C47: =C29*'Model Assumptions'!H18 -> 0.8 | D47: =D29*'Model Assumptions'!I18 -> 0.8 | E47: =E29*'Model Assumptions'!J18 -> 0.8 | F47: =F29*'Model Assumptions'!K18 -> 0.8 | G47: =G29*'Model Assumptions'!L18 -> 0.8 | H47: =H29*'Model Assumptions'!M18 -> 1.15 | I47: =I29*'Model Assumptions'!N18 -> 1.45 | ... M47: =M29*'Model Assumptions'!R18 -> 2.15
...

Sheet Rep and Marketing Details
B1: Rep & Marketing Details
B2: Fill in the fields in grey.
C5: 44562 | D5: =EDATE(C5,1) -> 44593 | E5: =EDATE(D5,1) -> 44621 | F5: =EDATE(E5,1) -> 44652 | G5: =EDATE(F5,1) -> 44682 | H5: =EDATE(G5,1) -> 44713 | I5: =EDATE(H5,1) -> 44743 | J5: =EDATE(I5,1) -> 44774 | K5: =EDATE(J5,1) -> 44805 | ... N5: =EDATE(M5,1) -> 44896
B6: Rep Quotas - $ ARR
B7: Rep 1 - Abby | C7: 33333 | D7: 33333 | E7: 33333 | F7: 33333 | G7: 33333 | H7: 33333 | I7: 33333 | J7: 33333 | K7: 33333 | L7: 33333 | M7: 33333 | N7: 33333
B8: Rep 2 - Danielle | G8: 33333 | H8: 33333 | I8: 33333 | J8: 33333 | K8: 33333 | L8: 33333 | M8: 33333 | N8: 33333
B9: Rep 3
B10: Total | C10: =SUM(C6:C9) -> 33333 | D10: =SUM(D6:D9) -> 33333 | E10: =SUM(E6:E9) -> 33333 | F10: =SUM(F6:F9) -> 33333 | G10: =SUM(G6:G9) -> 66666 | H10: =SUM(H6:H9) -> 66666 | I10: =SUM(I6:I9) -> 66666 | J10: =SUM(J6:J9) -> 66666 | ... N10: =SUM(N6:N9) -> 66666
B12: Rep Attainment - $ ARR
B13: Rep 1 - Abby | G13: 0
B14: Rep 2 - Danielle | G14: 0
B15: Rep 3
B17: Total (MRR) | C17: =SUM(C13:C15)/12 -> 0 | D17: =SUM(D13:D15)/12 -> 0 | E17: =SUM(E13:E15)/12 -> 0 | F17: =SUM(F13:F15)/12 -> 0 | G17: =SUM(G13:G15)/12 -> 0 | H17: =SUM(H13:H15)/12 -> 0 | I17: =SUM(I13:I15)/12 -> 0 | J17: =SUM(J13:J15)/12 -> 0 | ... N17: =SUM(N13:N15)/12 -> 0
B19: Rep 1 Attainment % | C19: =C13/C7 -> 0 | D19: =D13/D7 -> 0 | E19: =E13/E7 -> 0 | F19: =F13/F7 -> 0 | G19: =G13/G7 -> 0 | H19: =H13/H7 -> 0 | I19: =I13/I7 -> 0 | J19: =J13/J7 -> 0 | ... N19: =N13/N7 -> 0
B20: Rep 2 Attainment % | C20: =C14/C8 -> #DIV/0! | D20: =D14/D8 -> #DIV/0! | E20: =E14/E8 -> #DIV/0! | F20: =F14/F8 -> #DIV/0! | G20: =G14/G8 -> 0 | H20: =H14/H8 -> 0 | I20: =I14/I8 -> 0 | J20: =J14/J8 -> 0 | ... N20: =N14/N8 -> 0
B21: Rep 3 Attainment % | C21: =C15/C9 -> #DIV/0! | D21: =D15/D9 -> #DIV/0! | E21: =E15/E9 -> #DIV/0! | F21: =F15/F9 -> #DIV/0! | G21: =G15/G9 -> #DIV/0! | H21: =H15/H9 -> #DIV/0! | I21: =I15/I9 -> #DIV/0! | J21: =J15/J9 -> #DIV/0! | ... N21: =N15/N9 -> #DIV/0!
B22: Total Attainment % | C22: =C17/C10 -> 0 | D22: =D17/D10 -> 0 | E22: =E17/E10 -> 0 | F22: =F17/F10 -> 0 | G22: =G17/G10 -> 0 | H22: =H17/H10 -> 0 | I22: =I17/I10 -> 0 | J22: =J17/J10 -> 0 | ... N22: =N17/N10 -> 0
B24: Note: Rep OTE & Sales Costs
B25: Rep 1 - Abby | C25: 7476.66 | D25: 7476.66 | E25: 7476.66 | F25: 7476.66 | G25: 7476.66 | H25: 7867.34 | I25: 3738.33 | J25: 0 | K25: =J25 -> 0 | L25: =K25 -> 0 | M25: =L25 -> 0 | N25: =M25 -> 0
B26: Rep 2 - Danielle | C26: 8845.83 | D26: 8845.83 | E26: 8845.83 | F26: 8845.83 | G26: 8845.83 | H26: 9960.49 | I26: 9937.5 | J26: 9960.49 | K26: 9960.49 | L26: 9960.49 | M26: 9960.49 | N26: 9960.49
B27: Rep 3
B28: SDRs Total Cost - Lia | H28: 3736.21 | I28: 5439.96 | J28: 5439.96 | K28: 5439.96 | L28: 5439.96 | M28: 5439.96 | N28: 5439.96
B29: Managers and other total cost
B30: Total | C30: =SUM(C25:C29) -> 16322.49 | D30: =SUM(D25:D29) -> 16322.49 | E30: =SUM(E25:E29) -> 16322.49 | F30: =SUM(F25:F29) -> 16322.49 | G30: =SUM(G25:G29) -> 16322.49 | H30: =SUM(H25:H29) -> 21564.04 | I30: =SUM(I25:I29) -> 19115.79 | J30: =SUM(J25:J29) -> 15400.45 | ... N30: =SUM(N25:N29) -> 15400.45
B32: Rep Accounts Touched - #
B33: Rep 1 - Abby
B34: Rep 2 - Danielle
B35: Rep 3
B37: Total | C37: =SUM(C33:C35) -> 0 | D37: =SUM(D33:D35) -> 0 | E37: =SUM(E33:E35) -> 0 | F37: =SUM(F33:F35) -> 0 | G37: =SUM(G33:G35) -> 0 | H37: =SUM(H33:H35) -> 0 | I37: =SUM(I33:I35) -> 0 | J37: =SUM(J33:J35) -> 0 | ... N37: =SUM(N33:N35) -> 0
B39: Rep Deals - #
B40: Rep 1 - Abby | G40: 1
B41: Rep 2 - Danielle | G41: 5
B42: Rep 3
B43: Total | C43: =SUM(C40:C42) -> 0 | D43: =SUM(D40:D42) -> 0 | E43: =SUM(E40:E42) -> 0 | F43: =SUM(F40:F42) -> 0 | G43: =SUM(G40:G42) -> 6 | H43: =SUM(H40:H42) -> 0 | I43: =SUM(I40:I42) -> 0 | J43: =SUM(J40:J42) -> 0 | ... N43: =SUM(N40:N42) -> 0
B45: Closed Deals by Rep - #
B46: Rep 1 - Abby | C46: 2 | G46: 0
B47: Rep 2 - Danielle | G47: 0
B48: Rep 3
B50: Total | C50: =SUM(C46:C48) -> 2 | D50: =SUM(D46:D48) -> 0 | E50: =SUM(E46:E48) -> 0 | F50: =SUM(F46:F48) -> 0 | G50: =SUM(G46:G48) -> 0 | H50: =SUM(H46:H48) -> 0 | I50: =SUM(I46:I48) -> 0 | J50: =SUM(J46:J48) -> 0 | ... N50: =SUM(N46:N48) -> 0
B51: Rep 1 SQO to win rate | C51: =C46/C40 -> #DIV/0! | D51: =D46/D40 -> #DIV/0! | E51: =E46/E40 -> #DIV/0! | F51: =F46/F40 -> #DIV/0! | G51: =G46/G40 -> 0 | H51: =H46/H40 -> #DIV/0! | I51: =I46/I40 -> #DIV/0! | J51: =J46/J40 -> #DIV/0! | ... N51: =N46/N40 -> #DIV/0!
...

Sheet Copy of Studies Published Data 
A1: https://app.amplitude.com/analytics/rallyuxr/chart/o5w4lyo/edit/69zjz4ud
A2: slug | B2: close date | C2: quarter | D2: ACV | E2: 44652 | F2: 44682 | G2: 44713 | H2: 44743 | I2: 44774 | J2: 44805 | K2: 44835 | L2: 44866 | M2: 44896 | N2: 44986 | O2: 45017 | P2: 45047 | Q2: 45078 | R2: 45108 | S2: 45139 | T2: 45170 | U2: 45200 | V2: 45231 | W2: 45261 | X2: 45292 | Y2: 45323 | Z2: 45352
A3: hellofresh | B3: 44645 | C3: ="Q" & INT((MONTH(B3)-1)/3) + 1 & " " & YEAR(B3) -> Q1 2022 | D3: 25000 | E3: 0 | F3: 0 | G3: 0 | H3: 0 | I3: 1 | J3: 0 | K3: 0 | L3: 4 | M3: 0 | N3: 2 | O3: 2 | P3: 2 | Q3: 2 | R3: 5 | S3: 10 | T3: 10 | U3: 14 | V3: 14 | W3: 15 | X3: 16 | Y3: 16 | Z3: 16
A4: consensys | B4: 44795 | C4: ="Q" & INT((MONTH(B4)-1)/3) + 1 & " " & YEAR(B4) -> Q3 2022 | D4: 3000 | E4: 0 | F4: 0 | G4: 0 | H4: 0 | I4: 3 | J4: 7 | K4: 0 | L4: 0 | M4: 0 | N4: 3 | O4: 5 | P4: 6 | Q4: 6 | R4: 6 | S4: 6 | T4: 6 | U4: 6 | V4: 7 | W4: 7 | X4: 7 | Y4: 7 | Z4: 7
A5: pandadoc | B5: 44795 | C5: ="Q" & INT((MONTH(B5)-1)/3) + 1 & " " & YEAR(B5) -> Q3 2022 | D5: 7500 | E5: 0 | F5: 0 | G5: 0 | H5: 0 | I5: 19 | J5: 12 | K5: 9 | L5: 17 | M5: 15 | N5: 3 | O5: 25 | P5: 36 | Q5: 48 | R5: 58 | S5: 62 | T5: 67 | U5: 82 | V5: 89 | W5: 96 | X5: 103 | Y5: 111 | Z5: 114
A6: xplor_technologies | B6: 44795 | C6: ="Q" & INT((MONTH(B6)-1)/3) + 1 & " " & YEAR(B6) -> Q3 2022 | D6: 8000 | E6: 0 | F6: 0 | G6: 0 | H6: 0 | I6: 5 | J6: 5 | K6: 6 | L6: 8 | M6: 4 | N6: 6 | O6: 11 | P6: 16 | Q6: 19 | R6: 22 | S6: 24 | T6: 28 | U6: 29 | V6: 31 | W6: 34 | X6: 35 | Y6: 38 | Z6: 41
A7: angi | B7: 44856 | C7: ="Q" & INT((MONTH(B7)-1)/3) + 1 & " " & YEAR(B7) -> Q4 2022 | D7: 10000 | E7: 0 | F7: 0 | G7: 0 | H7: 0 | I7: 0 | J7: 1 | K7: 4 | L7: 2 | M7: 4 | N7: 7 | O7: 8 | P7: 15 | Q7: 16 | R7: 19 | S7: 19 | T7: 24 | U7: 30 | V7: 30 | W7: 31 | X7: 34 | Y7: 36 | Z7: 42
A8: snowplow | B8: 44857 | C8: ="Q" & INT((MONTH(B8)-1)/3) + 1 & " " & YEAR(B8) -> Q4 2022 | D8: 2000 | E8: 0 | F8: 0 | G8: 0 | H8: 0 | I8: 0 | J8: 0 | K8: 0 | L8: 0 | M8: 0 | N8: 2 | O8: 2 | P8: 4 | Q8: 5 | R8: 6 | S8: 9 | T8: 11 | U8: 13 | V8: 14 | W8: 15 | X8: 15 | Y8: 18 | Z8: 18
A9: findmypast | B9: 44887 | C9: ="Q" & INT((MONTH(B9)-1)/3) + 1 & " " & YEAR(B9) -> Q4 2022 | D9: 1200 | E9: 0 | F9: 0 | G9: 0 | H9: 0 | I9: 0 | J9: 0 | K9: 0 | L9: 3 | M9: 3 | N9: 12 | O9: 12 | P9: 16 | Q9: 19 | R9: 19 | S9: 19 | T9: 20 | U9: 22 | V9: 23 | W9: 24 | X9: 24 | Y9: 26 | Z9: 30
A10: predictive_index | B10: 44887 | C10: ="Q" & INT((MONTH(B10)-1)/3) + 1 & " " & YEAR(B10) -> Q4 2022 | D10: 2000 | E10: 0 | F10: 0 | G10: 0 | H10: 0 | I10: 0 | J10: 0 | K10: 3 | L10: 2 | M10: 2 | N10: 7 | O10: 8 | P10: 12 | Q10: 12 | R10: 13 | S10: 16 | T10: 19 | U10: 20 | V10: 22 | W10: 23 | X10: 26 | Y10: 27 | Z10: 27
A11: biorender | B11: 44917 | C11: ="Q" & INT((MONTH(B11)-1)/3) + 1 & " " & YEAR(B11) -> Q4 2022 | D11: 2000 | E11: 0 | F11: 0 | G11: 0 | H11: 0 | I11: 0 | J11: 0 | K11: 0 | L11: 0 | M11: 0 | N11: 7 | O11: 10 | P11: 13 | Q11: 21 | R11: 23 | S11: 31 | T11: 38 | U11: 39 | V11: 43 | W11: 46 | X11: 48 | Y11: 53 | Z11: 58
A12: checkr | B12: 44917 | C12: ="Q" & INT((MONTH(B12)-1)/3) + 1 & " " & YEAR(B12) -> Q4 2022 | D12: 10000 | E12: 0 | F12: 0 | G12: 0 | H12: 0 | I12: 0 | J12: 0 | K12: 0 | L12: 0 | M12: 0 | N12: 2 | O12: 2 | P12: 3 | Q12: 5 | R12: 5 | S12: 10 | T12: 11 | U12: 15 | V12: 19 | W12: 20 | X12: 22 | Y12: 25 | Z12: 28
A13: g-p | B13: 44917 | C13: ="Q" & INT((MONTH(B13)-1)/3) + 1 & " " & YEAR(B13) -> Q4 2022 | D13: 10000 | E13: 0 | F13: 0 | G13: 0 | H13: 0 | I13: 0 | J13: 0 | K13: 0 | L13: 0 | M13: 0 | N13: 0 | O13: 0 | P13: 1 | Q13: 2 | R13: 4 | S13: 10 | T13: 13 | U13: 15 | V13: 22 | W13: 23 | X13: 24 | Y13: 28 | Z13: 29
A14: teachable | B14: 44917 | C14: ="Q" & INT((MONTH(B14)-1)/3) + 1 & " " & YEAR(B14) -> Q4 2022 | D14: 3000 | E14: 0 | F14: 0 | G14: 0 | H14: 0 | I14: 0 | J14: 0 | K14: 0 | L14: 0 | M14: 1 | N14: 8 | O14: 11 | P14: 19 | Q14: 21 | R14: 26 | S14: 31 | T14: 35 | U14: 36 | V14: 43 | W14: 46 | X14: 50 | Y14: 55 | Z14: 57
... A48: cloudflare | B48: 45375 | C48: ="Q" & INT((MONTH(B48)-1)/3) + 1 & " " & YEAR(B48) -> Q1 2024 | D48: 20000 | E48: 0 | F48: 0 | G48: 0 | H48: 0 | I48: 0 | J48: 0 | K48: 0 | L48: 0 | M48: 0 | N48: 0 | O48: 0 | P48: 0 | Q48: 0 | R48: 0 | S48: 0 | T48: 0 | U48: 0 | V48: 0 | W48: 0 | X48: 0 | Y48: 0 | Z48: 1

Sheet Sheet5
A1: https://app.amplitude.com/analytics/rallyuxr/chart/o5w4lyo/edit/69zjz4ud
A2: slug | B2: close date | C2: quarter | D2: ACV | E2: 44652 | F2: 44682 | G2: 44713 | H2: 44743 | I2: 44774 | J2: 44805 | K2: 44835 | L2: 44866 | M2: 44896 | N2: 44986 | O2: 45017 | P2: 45047 | Q2: 45078 | R2: 45108 | S2: 45139 | T2: 45170 | U2: 45200 | V2: 45231 | W2: 45261 | X2: 45292 | Y2: 45323 | Z2: 45352
A3: hellofresh | B3: 44645 | C3: ="Q" & INT((MONTH(B3)-1)/3) + 1 & " " & YEAR(B3) -> Q1 2022 | D3: 25000 | E3: 0 | F3: 0 | G3: 0 | H3: 0 | I3: 1 | J3: 0 | K3: 0 | L3: 4 | M3: 0 | N3: 2 | O3: 0 | P3: 0 | Q3: 0 | R3: 3 | S3: 5 | T3: 0 | U3: 4 | V3: 0 | W3: 1 | X3: 1 | Y3: 0 | Z3: 0
A4: consensys | B4: 44795 | C4: ="Q" & INT((MONTH(B4)-1)/3) + 1 & " " & YEAR(B4) -> Q3 2022 | D4: 3000 | E4: 0 | F4: 0 | G4: 0 | H4: 0 | I4: 3 | J4: 7 | K4: 0 | L4: 0 | M4: 0 | N4: 3 | O4: 2 | P4: 1 | Q4: 0 | R4: 0 | S4: 0 | T4: 0 | U4: 0 | V4: 1 | W4: 0 | X4: 0 | Y4: 0 | Z4: 0
A5: pandadoc | B5: 44795 | C5: ="Q" & INT((MONTH(B5)-1)/3) + 1 & " " & YEAR(B5) -> Q3 2022 | D5: 7500 | E5: 0 | F5: 0 | G5: 0 | H5: 0 | I5: 19 | J5: 12 | K5: 9 | L5: 17 | M5: 15 | N5: 3 | O5: 22 | P5: 11 | Q5: 12 | R5: 10 | S5: 4 | T5: 5 | U5: 15 | V5: 7 | W5: 7 | X5: 7 | Y5: 8 | Z5: 3
A6: xplor_technologies | B6: 44795 | C6: ="Q" & INT((MONTH(B6)-1)/3) + 1 & " " & YEAR(B6) -> Q3 2022 | D6: 8000 | E6: 0 | F6: 0 | G6: 0 | H6: 0 | I6: 5 | J6: 5 | K6: 6 | L6: 8 | M6: 4 | N6: 6 | O6: 5 | P6: 5 | Q6: 3 | R6: 3 | S6: 2 | T6: 4 | U6: 1 | V6: 2 | W6: 3 | X6: 1 | Y6: 3 | Z6: 3
A7: angi | B7: 44856 | C7: ="Q" & INT((MONTH(B7)-1)/3) + 1 & " " & YEAR(B7) -> Q4 2022 | D7: 10000 | E7: 0 | F7: 0 | G7: 0 | H7: 0 | I7: 0 | J7: 1 | K7: 4 | L7: 2 | M7: 4 | N7: 7 | O7: 1 | P7: 7 | Q7: 1 | R7: 3 | S7: 0 | T7: 5 | U7: 6 | V7: 0 | W7: 1 | X7: 3 | Y7: 2 | Z7: 6
A8: snowplow | B8: 44857 | C8: ="Q" & INT((MONTH(B8)-1)/3) + 1 & " " & YEAR(B8) -> Q4 2022 | D8: 2000 | E8: 0 | F8: 0 | G8: 0 | H8: 0 | I8: 0 | J8: 0 | K8: 0 | L8: 0 | M8: 0 | N8: 2 | O8: 0 | P8: 2 | Q8: 1 | R8: 1 | S8: 3 | T8: 2 | U8: 2 | V8: 1 | W8: 1 | X8: 0 | Y8: 3 | Z8: 0
A9: findmypast | B9: 44887 | C9: ="Q" & INT((MONTH(B9)-1)/3) + 1 & " " & YEAR(B9) -> Q4 2022 | D9: 1200 | E9: 0 | F9: 0 | G9: 0 | H9: 0 | I9: 0 | J9: 0 | K9: 0 | L9: 3 | M9: 3 | N9: 12 | O9: 0 | P9: 4 | Q9: 3 | R9: 0 | S9: 0 | T9: 1 | U9: 2 | V9: 1 | W9: 1 | X9: 0 | Y9: 2 | Z9: 4
A10: predictive_index | B10: 44887 | C10: ="Q" & INT((MONTH(B10)-1)/3) + 1 & " " & YEAR(B10) -> Q4 2022 | D10: 2000 | E10: 0 | F10: 0 | G10: 0 | H10: 0 | I10: 0 | J10: 0 | K10: 3 | L10: 2 | M10: 2 | N10: 7 | O10: 1 | P10: 4 | Q10: 0 | R10: 1 | S10: 3 | T10: 3 | U10: 1 | V10: 2 | W10: 1 | X10: 3 | Y10: 1 | Z10: 0
A11: biorender | B11: 44917 | C11: ="Q" & INT((MONTH(B11)-1)/3) + 1 & " " & YEAR(B11) -> Q4 2022 | D11: 2000 | E11: 0 | F11: 0 | G11: 0 | H11: 0 | I11: 0 | J11: 0 | K11: 0 | L11: 0 | M11: 0 | N11: 7 | O11: 3 | P11: 3 | Q11: 8 | R11: 2 | S11: 8 | T11: 7 | U11: 1 | V11: 4 | W11: 3 | X11: 2 | Y11: 5 | Z11: 5
A12: checkr | B12: 44917 | C12: ="Q" & INT((MONTH(B12)-1)/3) + 1 & " " & YEAR(B12) -> Q4 2022 | D12: 10000 | E12: 0 | F12: 0 | G12: 0 | H12: 0 | I12: 0 | J12: 0 | K12: 0 | L12: 0 | M12: 0 | N12: 2 | O12: 0 | P12: 1 | Q12: 2 | R12: 0 | S12: 5 | T12: 1 | U12: 4 | V12: 4 | W12: 1 | X12: 2 | Y12: 3 | Z12: 3
A13: g-p | B13: 44917 | C13: ="Q" & INT((MONTH(B13)-1)/3) + 1 & " " & YEAR(B13) -> Q4 2022 | D13: 10000 | E13: 0 | F13: 0 | G13: 0 | H13: 0 | I13: 0 | J13: 0 | K13: 0 | L13: 0 | M13: 0 | N13: 0 | O13: 0 | P13: 1 | Q13: 1 | R13: 2 | S13: 6 | T13: 3 | U13: 2 | V13: 7 | W13: 1 | X13: 1 | Y13: 4 | Z13: 1
A14: teachable | B14: 44917 | C14: ="Q" & INT((MONTH(B14)-1)/3) + 1 & " " & YEAR(B14) -> Q4 2022 | D14: 3000 | E14: 0 | F14: 0 | G14: 0 | H14: 0 | I14: 0 | J14: 0 | K14: 0 | L14: 0 | M14: 1 | N14: 8 | O14: 3 | P14: 8 | Q14: 2 | R14: 5 | S14: 5 | T14: 4 | U14: 1 | V14: 7 | W14: 3 | X14: 4 | Y14: 5 | Z14: 2
... A48: cloudflare | B48: 45375 | C48: ="Q" & INT((MONTH(B48)-1)/3) + 1 & " " & YEAR(B48) -> Q1 2024 | D48: 20000 | E48: 0 | F48: 0 | G48: 0 | H48: 0 | I48: 0 | J48: 0 | K48: 0 | L48: 0 | M48: 0 | N48: 0 | O48: 0 | P48: 0 | Q48: 0 | R48: 0 | S48: 0 | T48: 0 | U48: 0 | V48: 0 | W48: 0 | X48: 0 | Y48: 0 | Z48: 1

Sheet Copy of ICP Customers
A1: slug | B1: close date | C1: quarter | D1: ACV
A2: hellofresh | B2: 44645 | C2: ="Q" & INT((MONTH(B2)-1)/3) + 1 & " " & YEAR(B2) -> Q1 2022 | D2: 25000
A3: consensys | B3: 44795 | C3: ="Q" & INT((MONTH(B3)-1)/3) + 1 & " " & YEAR(B3) -> Q3 2022 | D3: 3000
A4: pandadoc | B4: 44795 | C4: ="Q" & INT((MONTH(B4)-1)/3) + 1 & " " & YEAR(B4) -> Q3 2022 | D4: 7500
A5: xplor_technologies | B5: 44795 | C5: ="Q" & INT((MONTH(B5)-1)/3) + 1 & " " & YEAR(B5) -> Q3 2022 | D5: 8000
A6: angi | B6: 44856 | C6: ="Q" & INT((MONTH(B6)-1)/3) + 1 & " " & YEAR(B6) -> Q4 2022 | D6: 10000
A7: snowplow | B7: 44857 | C7: ="Q" & INT((MONTH(B7)-1)/3) + 1 & " " & YEAR(B7) -> Q4 2022 | D7: 2000
A8: findmypast | B8: 44887 | C8: ="Q" & INT((MONTH(B8)-1)/3) + 1 & " " & YEAR(B8) -> Q4 2022 | D8: 1200
A9: predictive_index | B9: 44887 | C9: ="Q" & INT((MONTH(B9)-1)/3) + 1 & " " & YEAR(B9) -> Q4 2022 | D9: 2000
A10: biorender | B10: 44917 | C10: ="Q" & INT((MONTH(B10)-1)/3) + 1 & " " & YEAR(B10) -> Q4 2022 | D10: 2000
A11: checkr | B11: 44917 | C11: ="Q" & INT((MONTH(B11)-1)/3) + 1 & " " & YEAR(B11) -> Q4 2022 | D11: 10000
A12: g-p | B12: 44917 | C12: ="Q" & INT((MONTH(B12)-1)/3) + 1 & " " & YEAR(B12) -> Q4 2022 | D12: 10000
A13: teachable | B13: 44917 | C13: ="Q" & INT((MONTH(B13)-1)/3) + 1 & " " & YEAR(B13) -> Q4 2022 | D13: 3000
... A47: cloudflare | B47: 45375 | C47: ="Q" & INT((MONTH(B47)-1)/3) + 1 & " " & YEAR(B47) -> Q1 2024 | D47: 20000

Sheet 📈 LIR 
C1: LIR - Studies Published Monthly
C3: KEY | H3: GOAL
C4: 1 | D4: Threshold | K4: % Customers Achieving LIR | L4: =SUM(V11:V51)/COUNT(V11:V51) -> #N/A
D5: LIR Achieved | K5: Goal | L5: 0.7
D6: LIR Not Achieved
C10: Company | D10: Month Closed | E10: ACV | F10: Contract Year | G10: ICP? | H10: <LIR Metric> | I10: Month 1 | J10: Month 2 | K10: Month 3 | L10: Month 4 | M10: Month 5 | N10: Month 6 | O10: Month 7 | P10: Month 8 | Q10: Month 9 | R10: Month 10 | S10: Month 11 | T10: Month 12 | V10: Current LIR | W10: Notes
D11: ='Studies (Monthly) RAW'!B4 -> 45047 | E11: ='Studies (Cum) RAW'!C4 -> 15000 | F11: 1 | G11: TRUE | H11: ='Studies (Monthly) RAW'!E4 -> 2 | I11: =IF(EQ('Studies (Monthly) RAW'!F4,""),"", (IF(('Studies (Monthly) RAW'!F4/$H11)<$C$4, 0, 1))) -> #NAME? | J11: =IF(EQ('Studies (Monthly) RAW'!G4, ""),"", (IF(('Studies (Monthly) RAW'!G4/$H11)<$C$4, 0, 1))) -> #NAME? | K11: =IF(EQ('Studies (Monthly) RAW'!H4,""),"", (IF(('Studies (Monthly) RAW'!H4/$H11)<$C$4, 0, 1))) -> #NAME? | L11: =IF(EQ('Studies (Monthly) RAW'!I4, ""),"", (IF(('Studies (Monthly) RAW'!I4/$H11)<$C$4, 0, 1))) -> #NAME? | M11: =IF(EQ('Studies (Monthly) RAW'!J4,""),"", (IF(('Studies (Monthly) RAW'!J4/$H11)<$C$4, 0, 1))) -> #NAME? | N11: =IF(EQ('Studies (Monthly) RAW'!K4, ""),"", (IF(('Studies (Monthly) RAW'!K4/$H11)<$C$4, 0, 1))) -> #NAME? | O11: =IF(EQ('Studies (Monthly) RAW'!L4,""),"", (IF(('Studies (Monthly) RAW'!L4/$H11)<$C$4, 0, 1))) -> #NAME? | P11: =IF(EQ('Studies (Monthly) RAW'!M4, ""),"", (IF(('Studies (Monthly) RAW'!M4/$H11)<$C$4, 0, 1))) -> #NAME? | Q11: =IF(EQ('Studies (Monthly) RAW'!N4,""),"", (IF(('Studies (Monthly) RAW'!N4/$H11)<$C$4, 0, 1))) -> #NAME? | R11: =IF(EQ('Studies (Monthly) RAW'!O4, ""),"", (IF(('Studies (Monthly) RAW'!O4/$H11)<$C$4, 0, 1))) -> #NAME? | S11: =IF(EQ('Studies (Monthly) RAW'!P4,""),"", (IF(('Studies (Monthly) RAW'!P4/$H11)<$C$4, 0, 1))) -> #NAME? | T11: =IF(EQ('Studies (Monthly) RAW'!Q4, ""),"", (IF(('Studies (Monthly) RAW'!Q4/$H11)<$C$4, 0, 1))) -> #NAME? | V11: {=LOOKUP(2,1/(H11:U11<>""),H11:U11)} -> 2
G12: FALSE | V12: {=LOOKUP(2,1/(H12:U12<>""),H12:U12)} -> #N/A
G13: TRUE | V13: {=LOOKUP(2,1/(H13:U13<>""),H13:U13)} -> #N/A
G14: TRUE | V14: {=LOOKUP(2,1/(H14:U14<>""),H14:U14)} -> #N/A
G15: TRUE | V15: {=LOOKUP(2,1/(H15:U15<>""),H15:U15)} -> #N/A
G16: TRUE | V16: {=LOOKUP(2,1/(H16:U16<>""),H16:U16)} -> #N/A
G17: TRUE | V17: {=LOOKUP(2,1/(H17:U17<>""),H17:U17)} -> #N/A
G18: FALSE | V18: {=LOOKUP(2,1/(H18:U18<>""),H18:U18)} -> #N/A
G19: TRUE | V19: {=LOOKUP(2,1/(H19:U19<>""),H19:U19)} -> #N/A
G20: TRUE | V20: {=LOOKUP(2,1/(H20:U20<>""),H20:U20)} -> #N/A
G21: FALSE | V21: {=LOOKUP(2,1/(H21:U21<>""),H21:U21)} -> #N/A
G22: TRUE | V22: {=LOOKUP(2,1/(H22:U22<>""),H22:U22)} -> #N/A
G23: TRUE | V23: {=LOOKUP(2,1/(H23:U23<>""),H23:U23)} -> #N/A
... G51: FALSE | V51: {=LOOKUP(2,1/(H51:U51<>""),H51:U51)} -> #N/A
C52: ='Studies (Monthly) RAW'!A45 -> 0 | D52: ='Studies (Monthly) RAW'!B45 -> #VALUE! | E52: ='Studies (Monthly) RAW'!C45 -> 0 | H52: ='Studies (Monthly) RAW'!E45 -> 0 | I52: =IF(EQ('Studies (Monthly) RAW'!F45,""),"", (IF(('Studies (Monthly) RAW'!F45/$H52)<$C$4, 0, 1))) -> #NAME? | J52: =IF(EQ('Studies (Monthly) RAW'!G45, ""),"", (IF(('Studies (Monthly) RAW'!G45/$H52)<$C$4, 0, 1))) -> #NAME? | K52: =IF(EQ('Studies (Monthly) RAW'!H45,""),"", (IF(('Studies (Monthly) RAW'!H45/$H52)<$C$4, 0, 1))) -> #NAME? | L52: =IF(EQ('Studies (Monthly) RAW'!I45, ""),"", (IF(('Studies (Monthly) RAW'!I45/$H52)<$C$4, 0, 1))) -> #NAME? | M52: =IF(EQ('Studies (Monthly) RAW'!J45,""),"", (IF(('Studies (Monthly) RAW'!J45/$H52)<$C$4, 0, 1))) -> #NAME? | N52: =IF(EQ('Studies (Monthly) RAW'!K45, ""),"", (IF(('Studies (Monthly) RAW'!K45/$H52)<$C$4, 0, 1))) -> #NAME? | O52: =IF(EQ('Studies (Monthly) RAW'!L45,""),"", (IF(('Studies (Monthly) RAW'!L45/$H52)<$C$4, 0, 1))) -> #NAME? | P52: =IF(EQ('Studies (Monthly) RAW'!M45, ""),"", (IF(('Studies (Monthly) RAW'!M45/$H52)<$C$4, 0, 1))) -> #NAME? | Q52: =IF(EQ('Studies (Monthly) RAW'!N45,""),"", (IF(('Studies (Monthly) RAW'!N45/$H52)<$C$4, 0, 1))) -> #NAME? | R52: =IF(EQ('Studies (Monthly) RAW'!O45, ""),"", (IF(('Studies (Monthly) RAW'!O45/$H52)<$C$4, 0, 1))) -> #NAME? | S52: =IF(EQ('Studies (Monthly) RAW'!P45,""),"", (IF(('Studies (Monthly) RAW'!P45/$H52)<$C$4, 0, 1))) -> #NAME? | T52: =IF(EQ('Studies (Monthly) RAW'!Q45, ""),"", (IF(('Studies (Monthly) RAW'!Q45/$H52)<$C$4, 0, 1))) -> #NAME?
C53: ='Studies (Monthly) RAW'!A46 -> 0 | D53: ='Studies (Monthly) RAW'!B46 -> #VALUE! | E53: ='Studies (Monthly) RAW'!C46 -> 0 | G53: ='Studies (Monthly) RAW'!D46 -> 0 | H53: ='Studies (Monthly) RAW'!E46 -> 0 | I53: =IF(EQ('Studies (Monthly) RAW'!F46,""),"", (IF(('Studies (Monthly) RAW'!F46/$H53)<$C$4, 0, 1))) -> #NAME? | J53: =IF(EQ('Studies (Monthly) RAW'!G46, ""),"", (IF(('Studies (Monthly) RAW'!G46/$H53)<$C$4, 0, 1))) -> #NAME? | K53: =IF(EQ('Studies (Monthly) RAW'!H46,""),"", (IF(('Studies (Monthly) RAW'!H46/$H53)<$C$4, 0, 1))) -> #NAME? | L53: =IF(EQ('Studies (Monthly) RAW'!I46, ""),"", (IF(('Studies (Monthly) RAW'!I46/$H53)<$C$4, 0, 1))) -> #NAME? | M53: =IF(EQ('Studies (Monthly) RAW'!J46,""),"", (IF(('Studies (Monthly) RAW'!J46/$H53)<$C$4, 0, 1))) -> #NAME? | N53: =IF(EQ('Studies (Monthly) RAW'!K46, ""),"", (IF(('Studies (Monthly) RAW'!K46/$H53)<$C$4, 0, 1))) -> #NAME? | O53: =IF(EQ('Studies (Monthly) RAW'!L46,""),"", (IF(('Studies (Monthly) RAW'!L46/$H53)<$C$4, 0, 1))) -> #NAME? | P53: =IF(EQ('Studies (Monthly) RAW'!M46, ""),"", (IF(('Studies (Monthly) RAW'!M46/$H53)<$C$4, 0, 1))) -> #NAME? | Q53: =IF(EQ('Studies (Monthly) RAW'!N46,""),"", (IF(('Studies (Monthly) RAW'!N46/$H53)<$C$4, 0, 1))) -> #NAME? | R53: =IF(EQ('Studies (Monthly) RAW'!O46, ""),"", (IF(('Studies (Monthly) RAW'!O46/$H53)<$C$4, 0, 1))) -> #NAME? | S53: =IF(EQ('Studies (Monthly) RAW'!P46,""),"", (IF(('Studies (Monthly) RAW'!P46/$H53)<$C$4, 0, 1))) -> #NAME? | T53: =IF(EQ('Studies (Monthly) RAW'!Q46, ""),"", (IF(('Studies (Monthly) RAW'!Q46/$H53)<$C$4, 0, 1))) -> #NAME?
C54: ='Studies (Monthly) RAW'!A47 -> 0 | D54: ='Studies (Monthly) RAW'!B47 -> #VALUE! | E54: ='Studies (Monthly) RAW'!C47 -> 0 | G54: ='Studies (Monthly) RAW'!D47 -> 0 | H54: ='Studies (Monthly) RAW'!E47 -> 0 | I54: =IF(EQ('Studies (Monthly) RAW'!F47,""),"", (IF(('Studies (Monthly) RAW'!F47/$H54)<$C$4, 0, 1))) -> #NAME? | J54: =IF(EQ('Studies (Monthly) RAW'!G47, ""),"", (IF(('Studies (Monthly) RAW'!G47/$H54)<$C$4, 0, 1))) -> #NAME? | K54: =IF(EQ('Studies (Monthly) RAW'!H47,""),"", (IF(('Studies (Monthly) RAW'!H47/$H54)<$C$4, 0, 1))) -> #NAME? | L54: =IF(EQ('Studies (Monthly) RAW'!I47, ""),"", (IF(('Studies (Monthly) RAW'!I47/$H54)<$C$4, 0, 1))) -> #NAME? | M54: =IF(EQ('Studies (Monthly) RAW'!J47,""),"", (IF(('Studies (Monthly) RAW'!J47/$H54)<$C$4, 0, 1))) -> #NAME? | N54: =IF(EQ('Studies (Monthly) RAW'!K47, ""),"", (IF(('Studies (Monthly) RAW'!K47/$H54)<$C$4, 0, 1))) -> #NAME? | O54: =IF(EQ('Studies (Monthly) RAW'!L47,""),"", (IF(('Studies (Monthly) RAW'!L47/$H54)<$C$4, 0, 1))) -> #NAME? | P54: =IF(EQ('Studies (Monthly) RAW'!M47, ""),"", (IF(('Studies (Monthly) RAW'!M47/$H54)<$C$4, 0, 1))) -> #NAME? | Q54: =IF(EQ('Studies (Monthly) RAW'!N47,""),"", (IF(('Studies (Monthly) RAW'!N47/$H54)<$C$4, 0, 1))) -> #NAME? | R54: =IF(EQ('Studies (Monthly) RAW'!O47, ""),"", (IF(('Studies (Monthly) RAW'!O47/$H54)<$C$4, 0, 1))) -> #NAME? | S54: =IF(EQ('Studies (Monthly) RAW'!P47,""),"", (IF(('Studies (Monthly) RAW'!P47/$H54)<$C$4, 0, 1))) -> #NAME? | T54: =IF(EQ('Studies (Monthly) RAW'!Q47, ""),"", (IF(('Studies (Monthly) RAW'!Q47/$H54)<$C$4, 0, 1))) -> #NAME?
C55: ='Studies (Monthly) RAW'!A48 -> 0 | D55: ='Studies (Monthly) RAW'!B48 -> #VALUE! | E55: ='Studies (Monthly) RAW'!C48 -> 0 | G55: ='Studies (Monthly) RAW'!D48 -> 0 | H55: ='Studies (Monthly) RAW'!E48 -> 0 | I55: =IF(EQ('Studies (Monthly) RAW'!F48,""),"", (IF(('Studies (Monthly) RAW'!F48/$H55)<$C$4, 0, 1))) -> #NAME? | J55: =IF(EQ('Studies (Monthly) RAW'!G48, ""),"", (IF(('Studies (Monthly) RAW'!G48/$H55)<$C$4, 0, 1))) -> #NAME? | K55: =IF(EQ('Studies (Monthly) RAW'!H48,""),"", (IF(('Studies (Monthly) RAW'!H48/$H55)<$C$4, 0, 1))) -> #NAME? | L55: =IF(EQ('Studies (Monthly) RAW'!I48, ""),"", (IF(('Studies (Monthly) RAW'!I48/$H55)<$C$4, 0, 1))) -> #NAME? | M55: =IF(EQ('Studies (Monthly) RAW'!J48,""),"", (IF(('Studies (Monthly) RAW'!J48/$H55)<$C$4, 0, 1))) -> #NAME? | N55: =IF(EQ('Studies (Monthly) RAW'!K48, ""),"", (IF(('Studies (Monthly) RAW'!K48/$H55)<$C$4, 0, 1))) -> #NAME? | O55: =IF(EQ('Studies (Monthly) RAW'!L48,""),"", (IF(('Studies (Monthly) RAW'!L48/$H55)<$C$4, 0, 1))) -> #NAME? | P55: =IF(EQ('Studies (Monthly) RAW'!M48, ""),"", (IF(('Studies (Monthly) RAW'!M48/$H55)<$C$4, 0, 1))) -> #NAME? | Q55: =IF(EQ('Studies (Monthly) RAW'!N48,""),"", (IF(('Studies (Monthly) RAW'!N48/$H55)<$C$4, 0, 1))) -> #NAME? | R55: =IF(EQ('Studies (Monthly) RAW'!O48, ""),"", (IF(('Studies (Monthly) RAW'!O48/$H55)<$C$4, 0, 1))) -> #NAME? | S55: =IF(EQ('Studies (Monthly) RAW'!P48,""),"", (IF(('Studies (Monthly) RAW'!P48/$H55)<$C$4, 0, 1))) -> #NAME? | T55: =IF(EQ('Studies (Monthly) RAW'!Q48, ""),"", (IF(('Studies (Monthly) RAW'!Q48/$H55)<$C$4, 0, 1))) -> #NAME?
C56: ='Studies (Monthly) RAW'!A49 -> 0 | D56: ='Studies (Monthly) RAW'!B49 -> #VALUE! | E56: ='Studies (Monthly) RAW'!C49 -> 0 | G56: ='Studies (Monthly) RAW'!D49 -> 0 | H56: ='Studies (Monthly) RAW'!E49 -> 0 | I56: =IF(EQ('Studies (Monthly) RAW'!F49,""),"", (IF(('Studies (Monthly) RAW'!F49/$H56)<$C$4, 0, 1))) -> #NAME? | J56: =IF(EQ('Studies (Monthly) RAW'!G49, ""),"", (IF(('Studies (Monthly) RAW'!G49/$H56)<$C$4, 0, 1))) -> #NAME? | K56: =IF(EQ('Studies (Monthly) RAW'!H49,""),"", (IF(('Studies (Monthly) RAW'!H49/$H56)<$C$4, 0, 1))) -> #NAME? | L56: =IF(EQ('Studies (Monthly) RAW'!I49, ""),"", (IF(('Studies (Monthly) RAW'!I49/$H56)<$C$4, 0, 1))) -> #NAME? | M56: =IF(EQ('Studies (Monthly) RAW'!J49,""),"", (IF(('Studies (Monthly) RAW'!J49/$H56)<$C$4, 0, 1))) -> #NAME? | N56: =IF(EQ('Studies (Monthly) RAW'!K49, ""),"", (IF(('Studies (Monthly) RAW'!K49/$H56)<$C$4, 0, 1))) -> #NAME? | O56: =IF(EQ('Studies (Monthly) RAW'!L49,""),"", (IF(('Studies (Monthly) RAW'!L49/$H56)<$C$4, 0, 1))) -> #NAME? | P56: =IF(EQ('Studies (Monthly) RAW'!M49, ""),"", (IF(('Studies (Monthly) RAW'!M49/$H56)<$C$4, 0, 1))) -> #NAME? | Q56: =IF(EQ('Studies (Monthly) RAW'!N49,""),"", (IF(('Studies (Monthly) RAW'!N49/$H56)<$C$4, 0, 1))) -> #NAME? | R56: =IF(EQ('Studies (Monthly) RAW'!O49, ""),"", (IF(('Studies (Monthly) RAW'!O49/$H56)<$C$4, 0, 1))) -> #NAME? | S56: =IF(EQ('Studies (Monthly) RAW'!P49,""),"", (IF(('Studies (Monthly) RAW'!P49/$H56)<$C$4, 0, 1))) -> #NAME? | T56: =IF(EQ('Studies (Monthly) RAW'!Q49, ""),"", (IF(('Studies (Monthly) RAW'!Q49/$H56)<$C$4, 0, 1))) -> #NAME?
C57: ='Studies (Monthly) RAW'!A50 -> 0 | D57: ='Studies (Monthly) RAW'!B50 -> #VALUE! | E57: ='Studies (Monthly) RAW'!C50 -> 0 | G57: ='Studies (Monthly) RAW'!D50 -> 0 | H57: ='Studies (Monthly) RAW'!E50 -> 0 | I57: =IF(EQ('Studies (Monthly) RAW'!F50,""),"", (IF(('Studies (Monthly) RAW'!F50/$H57)<$C$4, 0, 1))) -> #NAME? | J57: =IF(EQ('Studies (Monthly) RAW'!G50, ""),"", (IF(('Studies (Monthly) RAW'!G50/$H57)<$C$4, 0, 1))) -> #NAME? | K57: =IF(EQ('Studies (Monthly) RAW'!H50,""),"", (IF(('Studies (Monthly) RAW'!H50/$H57)<$C$4, 0, 1))) -> #NAME? | L57: =IF(EQ('Studies (Monthly) RAW'!I50, ""),"", (IF(('Studies (Monthly) RAW'!I50/$H57)<$C$4, 0, 1))) -> #NAME? | M57: =IF(EQ('Studies (Monthly) RAW'!J50,""),"", (IF(('Studies (Monthly) RAW'!J50/$H57)<$C$4, 0, 1))) -> #NAME? | N57: =IF(EQ('Studies (Monthly) RAW'!K50, ""),"", (IF(('Studies (Monthly) RAW'!K50/$H57)<$C$4, 0, 1))) -> #NAME? | O57: =IF(EQ('Studies (Monthly) RAW'!L50,""),"", (IF(('Studies (Monthly) RAW'!L50/$H57)<$C$4, 0, 1))) -> #NAME? | P57: =IF(EQ('Studies (Monthly) RAW'!M50, ""),"", (IF(('Studies (Monthly) RAW'!M50/$H57)<$C$4, 0, 1))) -> #NAME? | Q57: =IF(EQ('Studies (Monthly) RAW'!N50,""),"", (IF(('Studies (Monthly) RAW'!N50/$H57)<$C$4, 0, 1))) -> #NAME? | R57: =IF(EQ('Studies (Monthly) RAW'!O50, ""),"", (IF(('Studies (Monthly) RAW'!O50/$H57)<$C$4, 0, 1))) -> #NAME? | S57: =IF(EQ('Studies (Monthly) RAW'!P50,""),"", (IF(('Studies (Monthly) RAW'!P50/$H57)<$C$4, 0, 1))) -> #NAME? | T57: =IF(EQ('Studies (Monthly) RAW'!Q50, ""),"", (IF(('Studies (Monthly) RAW'!Q50/$H57)<$C$4, 0, 1))) -> #NAME?
C58: ='Studies (Monthly) RAW'!A51 -> 0 | D58: ='Studies (Monthly) RAW'!B51 -> #VALUE! | E58: ='Studies (Monthly) RAW'!C51 -> 0 | G58: ='Studies (Monthly) RAW'!D51 -> 0 | H58: ='Studies (Monthly) RAW'!E51 -> 0 | I58: =IF(EQ('Studies (Monthly) RAW'!F51,""),"", (IF(('Studies (Monthly) RAW'!F51/$H58)<$C$4, 0, 1))) -> #NAME? | J58: =IF(EQ('Studies (Monthly) RAW'!G51, ""),"", (IF(('Studies (Monthly) RAW'!G51/$H58)<$C$4, 0, 1))) -> #NAME? | K58: =IF(EQ('Studies (Monthly) RAW'!H51,""),"", (IF(('Studies (Monthly) RAW'!H51/$H58)<$C$4, 0, 1))) -> #NAME? | L58: =IF(EQ('Studies (Monthly) RAW'!I51, ""),"", (IF(('Studies (Monthly) RAW'!I51/$H58)<$C$4, 0, 1))) -> #NAME? | M58: =IF(EQ('Studies (Monthly) RAW'!J51,""),"", (IF(('Studies (Monthly) RAW'!J51/$H58)<$C$4, 0, 1))) -> #NAME? | N58: =IF(EQ('Studies (Monthly) RAW'!K51, ""),"", (IF(('Studies (Monthly) RAW'!K51/$H58)<$C$4, 0, 1))) -> #NAME? | O58: =IF(EQ('Studies (Monthly) RAW'!L51,""),"", (IF(('Studies (Monthly) RAW'!L51/$H58)<$C$4, 0, 1))) -> #NAME? | P58: =IF(EQ('Studies (Monthly) RAW'!M51, ""),"", (IF(('Studies (Monthly) RAW'!M51/$H58)<$C$4, 0, 1))) -> #NAME? | Q58: =IF(EQ('Studies (Monthly) RAW'!N51,""),"", (IF(('Studies (Monthly) RAW'!N51/$H58)<$C$4, 0, 1))) -> #NAME? | R58: =IF(EQ('Studies (Monthly) RAW'!O51, ""),"", (IF(('Studies (Monthly) RAW'!O51/$H58)<$C$4, 0, 1))) -> #NAME? | S58: =IF(EQ('Studies (Monthly) RAW'!P51,""),"", (IF(('Studies (Monthly) RAW'!P51/$H58)<$C$4, 0, 1))) -> #NAME? | T58: =IF(EQ('Studies (Monthly) RAW'!Q51, ""),"", (IF(('Studies (Monthly) RAW'!Q51/$H58)<$C$4, 0, 1))) -> #NAME?
C59: ='Studies (Monthly) RAW'!A52 -> 0 | D59: ='Studies (Monthly) RAW'!B52 -> #VALUE! | E59: ='Studies (Monthly) RAW'!C52 -> 0 | G59: ='Studies (Monthly) RAW'!D52 -> 0 | H59: ='Studies (Monthly) RAW'!E52 -> 0 | I59: =IF(EQ('Studies (Monthly) RAW'!F52,""),"", (IF(('Studies (Monthly) RAW'!F52/$H59)<$C$4, 0, 1))) -> #NAME? | J59: =IF(EQ('Studies (Monthly) RAW'!G52, ""),"", (IF(('Studies (Monthly) RAW'!G52/$H59)<$C$4, 0, 1))) -> #NAME? | K59: =IF(EQ('Studies (Monthly) RAW'!H52,""),"", (IF(('Studies (Monthly) RAW'!H52/$H59)<$C$4, 0, 1))) -> #NAME? | L59: =IF(EQ('Studies (Monthly) RAW'!I52, ""),"", (IF(('Studies (Monthly) RAW'!I52/$H59)<$C$4, 0, 1))) -> #NAME? | M59: =IF(EQ('Studies (Monthly) RAW'!J52,""),"", (IF(('Studies (Monthly) RAW'!J52/$H59)<$C$4, 0, 1))) -> #NAME? | N59: =IF(EQ('Studies (Monthly) RAW'!K52, ""),"", (IF(('Studies (Monthly) RAW'!K52/$H59)<$C$4, 0, 1))) -> #NAME? | O59: =IF(EQ('Studies (Monthly) RAW'!L52,""),"", (IF(('Studies (Monthly) RAW'!L52/$H59)<$C$4, 0, 1))) -> #NAME? | P59: =IF(EQ('Studies (Monthly) RAW'!M52, ""),"", (IF(('Studies (Monthly) RAW'!M52/$H59)<$C$4, 0, 1))) -> #NAME? | Q59: =IF(EQ('Studies (Monthly) RAW'!N52,""),"", (IF(('Studies (Monthly) RAW'!N52/$H59)<$C$4, 0, 1))) -> #NAME? | R59: =IF(EQ('Studies (Monthly) RAW'!O52, ""),"", (IF(('Studies (Monthly) RAW'!O52/$H59)<$C$4, 0, 1))) -> #NAME? | S59: =IF(EQ('Studies (Monthly) RAW'!P52,""),"", (IF(('Studies (Monthly) RAW'!P52/$H59)<$C$4, 0, 1))) -> #NAME? | T59: =IF(EQ('Studies (Monthly) RAW'!Q52, ""),"", (IF(('Studies (Monthly) RAW'!Q52/$H59)<$C$4, 0, 1))) -> #NAME?
